Workbook

Sheet Trade Book
A1: No | B1: Day | C1: Date | D1: Sell Algo(Angel One) | E1: Brokerage(Angel One) | F1: Other Charges(Angel One) | G1: Total Charges(Angel One) | H1: Final Net(Angel One) | I1: Sell Algo(Mummy) | J1: Brokerage(Mummy) | K1: Other charge | L1: Final Net(Finvasia) | M1: Total Charge(finvasia) | N1: Algos | O1: algo charges | P1: Charges | Q1: Profit | R1: Overall | S1: DD | T1: 50 Avg Profit | U1: 100 Avg Profit | V1: 100 Avg Charge | W1: Charge/Profit Ratio | X1: Capital | Y1: 100 D Avg Capital | Z1: Profit/Capital Ratio(bps)
R2: 0 | S2: 0 | X2: 1200000
A3: 1 | B3: Tuesday | C3: 45748 | I3: =10441-12512 -> -2071 | J3: 1750 | N3: 17 | O3: =ROUNDUP((N3 - 3)*12.5 + 62.5,0) -> 238 | P3: =J3+O3 -> 1988 | Q3: =IF(I3 = "N/A","",SUM(I3)-P3) -> -4059 | R3: =R2+Q3 -> -4059 | S3: =IF(I3 = "N/A","0",R3-MAX($R$1:R3)) -> -4059 | X3: 1200000
A4: =A3+1 -> 2 | B4: Wednesday | C4: 45749 | I4: 6518 | J4: 298 | N4: 8 | O4: =ROUNDUP((N4 - 3)*12.5 + 62.5,0) -> 125 | P4: =J4+O4 -> 423 | Q4: =IF(I4 = "N/A","",SUM(I4)-P4) -> 6095 | R4: =R3+Q4 -> 2036 | S4: =IF(I4 = "N/A","0",R4-MAX($R$1:R4)) -> 0 | X4: 1200000
A5: =A4+1 -> 3 | B5: Thursday | C5: 45750 | I5: 10567 | J5: 130 | N5: 8 | O5: =ROUNDUP((N5 - 3)*12.5 + 62.5,0) -> 125 | P5: =J5+O5 -> 255 | Q5: =IF(I5 = "N/A","",SUM(I5)-P5) -> 10312 | R5: =R4+Q5 -> 12348 | S5: =IF(I5 = "N/A","0",R5-MAX($R$1:R5)) -> 0 | X5: 1200000
A6: =A5+1 -> 4 | B6: Friday | C6: 45751 | I6: =10281-1607 -> 8674 | J6: 310 | N6: 6 | O6: =ROUNDUP((N6 - 3)*12.5 + 62.5,0) -> 100 | P6: =J6+O6 -> 410 | Q6: =IF(I6 = "N/A","",SUM(I6)-P6) -> 8264 | R6: =R5+Q6 -> 20612 | S6: =IF(I6 = "N/A","0",R6-MAX($R$1:R6)) -> 0 | X6: 1200000
A7: =A6+1 -> 5 | B7: Monday | C7: 45754 | I7: 442 | J7: 3110 | N7: 14 | O7: =ROUNDUP((N7 - 3)*12.5 + 62.5,0) -> 200 | P7: =J7+O7 -> 3310 | Q7: =IF(I7 = "N/A","",SUM(I7)-P7) -> -2868 | R7: =R6+Q7 -> 17744 | S7: =IF(I7 = "N/A","0",R7-MAX($R$1:R7)) -> -2868 | X7: 1200000
A8: =A7+1 -> 6 | B8: Tuesday | C8: 45755 | I8: 5773 | J8: 1550 | N8: 15 | O8: =ROUNDUP((N8 - 3)*12.5 + 62.5,0) -> 213 | P8: =J8+O8 -> 1763 | Q8: =IF(I8 = "N/A","",SUM(I8)-P8) -> 4010 | R8: =R7+Q8 -> 21754 | S8: =IF(I8 = "N/A","0",R8-MAX($R$1:R8)) -> 0 | X8: 1200000
A9: =A8+1 -> 7 | B9: Wednesday | C9: 45756 | I9: 13822 | J9: 113 | N9: 6 | O9: =ROUNDUP((N9 - 3)*12.5 + 62.5,0) -> 100 | P9: =J9+O9 -> 213 | Q9: =IF(I9 = "N/A","",SUM(I9)-P9) -> 13609 | R9: =R8+Q9 -> 35363 | S9: =IF(I9 = "N/A","0",R9-MAX($R$1:R9)) -> 0 | X9: 1200000
A10: =A9+1 -> 8 | B10: Thursday | C10: 45757 | I10: N/A | J10: 0 | N10: 8 | O10: =ROUNDUP((N10 - 3)*12.5 + 62.5,0) -> 125 | P10: =J10+O10 -> 125 | Q10: =IF(I10 = "N/A","",SUM(I10)-P10) | R10: =R9+Q10 -> 35363 | S10: =IF(I10 = "N/A","0",R10-MAX($R$1:R10)) -> 0 | X10: 1200000
A11: =A10+1 -> 9 | B11: Friday | C11: 45758 | I11: 6195 | J11: 979 | N11: 8 | O11: =ROUNDUP((N11 - 3)*12.5 + 62.5,0) -> 125 | P11: =J11+O11 -> 1104 | Q11: =IF(I11 = "N/A","",SUM(I11)-P11) -> 5091 | R11: =R10+Q11 -> 40454 | S11: =IF(I11 = "N/A","0",R11-MAX($R$1:R11)) -> 0 | X11: 1200000
A12: =A11+1 -> 10 | B12: Monday | C12: 45761 | I12: N/A | J12: 0 | N12: 8 | O12: =ROUNDUP((N12 - 3)*12.5 + 62.5,0) -> 125 | P12: =J12+O12 -> 125 | Q12: =IF(I12 = "N/A","",SUM(I12)-P12) | R12: =R11+Q12 -> 40454 | S12: =IF(I12 = "N/A","0",R12-MAX($R$1:R12)) -> 0 | X12: 1200000
A13: =A12+1 -> 11 | B13: Tuesday | C13: 45762 | I13: 543 | J13: 190 | N13: 8 | O13: =ROUNDUP((N13 - 3)*12.5 + 62.5,0) -> 125 | P13: =J13+O13 -> 315 | Q13: =IF(I13 = "N/A","",SUM(I13)-P13) -> 228 | R13: =R12+Q13 -> 40682 | S13: =IF(I13 = "N/A","0",R13-MAX($R$1:R13)) -> 0 | X13: 1200000
A14: =A13+1 -> 12 | B14: Wednesday | C14: 45763 | I14: =753-726 -> 27 | J14: =30+380 -> 410 | N14: 8 | O14: =ROUNDUP((N14 - 3)*12.5 + 62.5,0) -> 125 | P14: =J14+O14 -> 535 | Q14: =IF(I14 = "N/A","",SUM(I14)-P14) -> -508 | R14: =R13+Q14 -> 40174 | S14: =IF(I14 = "N/A","0",R14-MAX($R$1:R14)) -> -508 | X14: 1200000
A15: =A14+1 -> 13 | B15: Thursday | C15: 45764 | I15: -13000 | J15: 0 | N15: 11 | O15: =ROUNDUP((N15 - 3)*12.5 + 62.5,0) -> 163 | P15: =J15+O15 -> 163 | Q15: =IF(I15 = "N/A","",SUM(I15)-P15) -> -13163 | R15: =R14+Q15 -> 27011 | S15: =IF(I15 = "N/A","0",R15-MAX($R$1:R15)) -> -13671 | X15: 1200000
A16: =A15+1 -> 14 | B16: Friday | C16: 45765 | I16: 5898 | J16: 198 | N16: 14 | O16: =ROUNDUP((N16 - 3)*12.5 + 62.5,0) -> 200 | P16: =J16+O16 -> 398 | Q16: =IF(I16 = "N/A","",SUM(I16)-P16) -> 5500 | R16: =R15+Q16 -> 32511 | S16: =IF(I16 = "N/A","0",R16-MAX($R$1:R16)) -> -8171 | X16: 1200000
A17: =A16+1 -> 15 | B17: Monday | C17: 45768 | I17: N/A | J17: 160 | N17: 14 | O17: =ROUNDUP((N17 - 3)*12.5 + 62.5,0) -> 200 | P17: =J17+O17 -> 360 | Q17: =IF(I17 = "N/A","",SUM(I17)-P17) | R17: =R16+Q17 -> 32511 | S17: =IF(I18 = "N/A","0",R17-MAX($R$1:R17)) -> -8171 | X17: 1200000
A18: =A17+1 -> 16 | B18: Tuesday | C18: 45769 | I18: 4581 | J18: 3000 | N18: 14 | O18: =ROUNDUP((N18 - 3)*12.5 + 62.5,0) -> 200 | P18: =J18+O18 -> 3200 | Q18: =IF(I18 = "N/A","",SUM(I18)-P18) -> 1381 | R18: =R17+Q18 -> 33892 | S18: =IF(I19 = "N/A","0",R18-MAX($R$1:R18)) -> -6790 | X18: 1200000
A19: =A18+1 -> 17 | B19: Wednesday | C19: 45770 | I19: -13000 | J19: 1000 | N19: 15 | O19: =ROUNDUP((N19 - 3)*12.5 + 62.5,0) -> 213 | P19: =J19+O19 -> 1213 | Q19: =IF(I19 = "N/A","",SUM(I19)-P19) -> -14213 | R19: =R18+Q19 -> 19679 | S19: =IF(I20 = "N/A","0",R19-MAX($R$1:R19)) -> -21003 | X19: 1200000
A20: =A19+1 -> 18 | B20: Thursday | C20: 45771 | I20: -17000 | J20: 0 | N20: 8 | O20: =ROUNDUP((N20 - 3)*12.5 + 62.5,0) -> 125 | P20: =J20+O20 -> 125 | Q20: =IF(I20 = "N/A","",SUM(I20)-P20) -> -17125 | R20: =R19+Q20 -> 2554 | S20: =IF(I289 = "N/A","0",R20-MAX($R$1:R20)) -> -38128 | X20: 1200000
A21: 19 | B21: Monday | C21: 28 Apr 25 | I21: -4852.5 | J21: 226.66 | N21: 8 | O21: =ROUNDUP((N21 - 3)*12.5 + 62.5,0) -> 125 | P21: =ROUND(J21+O21,0) -> 352 | Q21: =IF(I21 = "N/A","",ROUND(SUM(I21)-P21,0)) -> -5205 | R21: =R20+Q21 -> -2651 | S21: =IF(I290 = "N/A","0",R21-MAX($R$1:R21)) -> -43333 | X21: 1200000
A22: 20 | B22: Tuesday | C22: 29 Apr 25 | I22: 763 | J22: 430.03 | N22: 8 | O22: =ROUNDUP((N22 - 3)*12.5 + 62.5,0) -> 125 | P22: =ROUND(J22+O22,0) -> 555 | Q22: =IF(I22 = "N/A","",ROUND(SUM(I22)-P22,0)) -> 208 | R22: =R21+Q22 -> -2443 | S22: =IF(I291 = "N/A","0",R22-MAX($R$1:R22)) -> -43125 | X22: 1200000
A23: 21 | B23: Wednesday | C23: 30 Apr 25 | I23: -6753.75 | J23: 830.17 | N23: 8 | O23: =ROUNDUP((N23 - 3)*12.5 + 62.5,0) -> 125 | P23: =ROUND(J23+O23,0) -> 955 | Q23: =IF(I23 = "N/A","",ROUND(SUM(I23)-P23,0)) -> -7709 | R23: =R22+Q23 -> -10152 | S23: =IF(I292 = "N/A","0",R23-MAX($R$1:R23)) -> -50834 | X23: 1200000
A24: 22 | B24: Friday | C24: 2 May 25 | I24: 4586.25 | J24: 853.7 | N24: 8 | O24: =ROUNDUP((N24 - 3)*12.5 + 62.5,0) -> 125 | P24: =ROUND(J24+O24,0) -> 979 | Q24: =IF(I24 = "N/A","",ROUND(SUM(I24)-P24,0)) -> 3607 | R24: =R23+Q24 -> -6545 | S24: =IF(I293 = "N/A","0",R24-MAX($R$1:R24)) -> -47227 | X24: 1200000
A25: 23 | B25: Monday | C25: 5 May 25 | I25: -3540 | J25: 282.76 | N25: 8 | O25: =ROUNDUP((N25 - 3)*12.5 + 62.5,0) -> 125 | P25: =ROUND(J25+O25,0) -> 408 | Q25: =IF(I25 = "N/A","",ROUND(SUM(I25)-P25,0)) -> -3948 | R25: =R24+Q25 -> -10493 | S25: =IF(I294 = "N/A","0",R25-MAX($R$1:R25)) -> -51175 | X25: 1200000
A26: 24 | B26: Tuesday | C26: 6 May 25 | I26: 5064 | J26: 228.56 | N26: 8 | O26: =ROUNDUP((N26 - 3)*12.5 + 62.5,0) -> 125 | P26: =ROUND(J26+O26,0) -> 354 | Q26: =IF(I26 = "N/A","",ROUND(SUM(I26)-P26,0)) -> 4710 | R26: =R25+Q26 -> -5783 | S26: =IF(I295 = "N/A","0",R26-MAX($R$1:R26)) -> -46465 | X26: 1200000
A27: 25 | B27: Wednesday | C27: 7 May 25 | I27: 3521.25 | J27: 194.5 | N27: 8 | O27: =ROUNDUP((N27 - 3)*12.5 + 62.5,0) -> 125 | P27: =ROUND(J27+O27,0) -> 320 | Q27: =IF(I27 = "N/A","",ROUND(SUM(I27)-P27,0)) -> 3201 | R27: =R26+Q27 -> -2582 | S27: =IF(I296 = "N/A","0",R27-MAX($R$1:R27)) -> -43264 | X27: 1200000
A28: 26 | B28: Thursday | C28: 8 May 25 | I28: 4170 | J28: 369.78 | N28: 8 | O28: =ROUNDUP((N28 - 3)*12.5 + 62.5,0) -> 125 | P28: =ROUND(J28+O28,0) -> 495 | Q28: =IF(I28 = "N/A","",ROUND(SUM(I28)-P28,0)) -> 3675 | R28: =R27+Q28 -> 1093 | S28: =IF(I297 = "N/A","0",R28-MAX($R$1:R28)) -> -39589 | X28: 1200000
A29: 27 | B29: Friday | C29: 9 May 25 | I29: -1496.25 | J29: 757.84 | N29: 8 | O29: =ROUNDUP((N29 - 3)*12.5 + 62.5,0) -> 125 | P29: =ROUND(J29+O29,0) -> 883 | Q29: =IF(I29 = "N/A","",ROUND(SUM(I29)-P29,0)) -> -2379 | R29: =R28+Q29 -> -1286 | S29: =IF(I298 = "N/A","0",R29-MAX($R$1:R29)) -> -41968 | X29: 1200000
A30: 28 | B30: Monday | C30: 12 May 25 | I30: -13657.5 | J30: 936.18 | N30: 16 | O30: =ROUNDUP((N30 - 3)*12.5 + 62.5,0) -> 225 | P30: =ROUND(J30+O30,0) -> 1161 | Q30: =IF(I30 = "N/A","",ROUND(SUM(I30)-P30,0)) -> -14819 | R30: =R29+Q30 -> -16105 | S30: =IF(I299 = "N/A","0",R30-MAX($R$1:R30)) -> -56787 | X30: 1200000
A31: 29 | B31: Tuesday | C31: 13 May 25 | I31: 2742 | J31: 1350.62 | N31: 20 | O31: =ROUNDUP((N31 - 3)*12.5 + 62.5,0) -> 275 | P31: =ROUND(J31+O31,0) -> 1626 | Q31: =IF(I31 = "N/A","",ROUND(SUM(I31)-P31,0)) -> 1116 | R31: =R30+Q31 -> -14989 | S31: =IF(I300 = "N/A","0",R31-MAX($R$1:R31)) -> -55671 | X31: 1200000
A32: 30 | B32: Wednesday | C32: 14 May 25 | I32: 5272.5 | J32: 194 | N32: 20 | O32: =ROUNDUP((N32 - 3)*12.5 + 62.5,0) -> 275 | P32: =ROUND(J32+O32,0) -> 469 | Q32: =IF(I32 = "N/A","",ROUND(SUM(I32)-P32,0)) -> 4804 | R32: =R31+Q32 -> -10185 | S32: =IF(I301 = "N/A","0",R32-MAX($R$1:R32)) -> -50867 | X32: 1200000
... A44: 42 | B44: Thursday | C44: 29 May 25 | I44: -8000 | J44: 0 | N44: 8 | O44: =ROUNDUP((N44 - 3)*12.5 + 62.5,0) -> 125 | P44: =ROUND(J44+O44,0) -> 125 | Q44: =IF(I44 = "N/A","",ROUND(SUM(I44)-P44,0)) -> -8125 | R44: =R43+Q44 -> 25105 | S44: =IF(I313 = "N/A","0",R44-MAX($R$1:R44)) -> -15577 | X44: 1200000
A45: 44 | B45: Friday | C45: 30 May 25 | I45: -8000 | J45: 0 | N45: 8 | O45: =ROUNDUP((N45 - 3)*12.5 + 62.5,0) -> 125 | P45: =ROUND(J45+O45,0) -> 125 | Q45: =IF(I45 = "N/A","",ROUND(SUM(I45)-P45,0)) -> -8125 | R45: =R44+Q45 -> 16980 | S45: =IF(I315 = "N/A","0",R45-MAX($R$1:R45)) -> -23702 | X45: 1200000
A46: 45 | B46: Monday | C46: 2 Jun 25 | I46: 7598 | J46: 716.21 | N46: 8 | O46: =ROUNDUP((N46 - 3)*12.5 + 62.5,0) -> 125 | P46: =ROUND(J46+O46,0) -> 841 | Q46: =IF(I46 = "N/A","",ROUND(SUM(I46)-P46,0)) -> 6757 | R46: =R45+Q46 -> 23737 | S46: =IF(I316 = "N/A","0",R46-MAX($R$1:R46)) -> -16945 | X46: 1200000
A47: 46 | B47: Tuesday | C47: 3 Jun 25 | I47: 5953.5 | J47: 1124.54 | N47: 8 | O47: =ROUNDUP((N47 - 3)*12.5 + 62.5,0) -> 125 | P47: =ROUND(J47+O47,0) -> 1250 | Q47: =IF(I47 = "N/A","",ROUND(SUM(I47)-P47,0)) -> 4704 | R47: =R46+Q47 -> 28441 | S47: =IF(I317 = "N/A","0",R47-MAX($R$1:R47)) -> -12241 | X47: 1200000
A48: 47 | B48: Wednesday | C48: 4 Jun 25 | I48: 1841.25 | J48: 504.7 | N48: 8 | O48: =ROUNDUP((N48 - 3)*12.5 + 62.5,0) -> 125 | P48: =ROUND(J48+O48,0) -> 630 | Q48: =IF(I48 = "N/A","",ROUND(SUM(I48)-P48,0)) -> 1211 | R48: =R47+Q48 -> 29652 | S48: =IF(I318 = "N/A","0",R48-MAX($R$1:R48)) -> -11030 | X48: 1200000
A49: 48 | B49: Thursday | C49: 5 Jun 25 | I49: 1706.25 | J49: 935 | N49: 20 | O49: =ROUNDUP((N49 - 3)*12.5 + 62.5,0) -> 275 | P49: =ROUND(J49+O49,0) -> 1210 | Q49: =IF(I49 = "N/A","",ROUND(SUM(I49)-P49,0)) -> 496 | R49: =R48+Q49 -> 30148 | S49: =IF(I319 = "N/A","0",R49-MAX($R$1:R49)) -> -10534 | X49: 1200000
A50: 49 | B50: Friday | C50: 6 Jun 25 | I50: 2691 | J50: 434.67 | N50: 5 | O50: =ROUNDUP((N50 - 3)*12.5 + 62.5,0) -> 88 | P50: =ROUND(J50+O50,0) -> 523 | Q50: =IF(I50 = "N/A","",ROUND(SUM(I50)-P50,0)) -> 2168 | R50: =R49+Q50 -> 32316 | S50: =IF(I320 = "N/A","0",R50-MAX($R$1:R50)) -> -8366 | X50: 1200000
A51: 50 | B51: Monday | C51: 9 Jun 25 | I51: 8606.25 | J51: 149.47 | N51: 8 | O51: =ROUNDUP((N51 - 3)*12.5 + 62.5,0) -> 125 | P51: =ROUND(J51+O51,0) -> 274 | Q51: =IF(I51 = "N/A","",ROUND(SUM(I51)-P51,0)) -> 8332 | R51: =R50+Q51 -> 40648 | S51: =IF(I321 = "N/A","0",R51-MAX($R$1:R51)) -> -34 | X51: 1200000
...

Sheet Monthly returns 2025-26
B1: Monthly Gain | C1: Trading Gain | D1: Capital | E1: Trading gain in% | F1: Trading gain Avg 3 mnth
B2: 45748 | C2: =SUM('Trade Book'!Q3:Q23) -> -10152 | D2: 1200000 | E2: =IF(C2 ="N/A","", ROUND(C2*100/D2,2)) -> -0.85
B3: 45778 | C3: =SUM('Trade Book'!Q24:Q45) -> 27132 | D3: 1200000 | E3: =IF(C3 ="N/A","", ROUND(C3*100/D3,2)) -> 2.26
B4: 45809 | C4: =SUM('Trade Book'!Q46:Q66) -> 6250 | D4: 1200000 | E4: =IF(C4 ="N/A","", ROUND(C4*100/D4,2)) -> 0.52 | F4: =ROUND(AVERAGE(E2:E4),2) -> 0.64
B5: 45839 | C5: =SUM('Trade Book'!Q67:Q89) -> 25899 | D5: 1200000 | E5: =IF(C5 ="N/A","", ROUND(C5*100/D5,2)) -> 2.16 | F5: =ROUND(AVERAGE(E3:E5),2) -> 1.65
B6: 45870 | C6: =SUM('Trade Book'!Q90:Q108) -> 53958 | D6: 1200000 | E6: =IF(C6 ="N/A","", ROUND(C6*100/D6,2)) -> 4.5 | F6: =ROUND(AVERAGE(E4:E6),2) -> 2.39
B7: 45901 | C7: =SUM('Trade Book'!Q109:Q130) -> 64721 | D7: 1200000 | E7: =IF(C7 ="N/A","", ROUND(C7*100/D7,2)) -> 5.39 | F7: =ROUND(AVERAGE(E5:E7),2) -> 4.02
B8: 45931 | C8: =SUM('Trade Book'!Q131:Q150) -> 12296 | D8: 1200000 | E8: =IF(C8 ="N/A","", ROUND(C8*100/D8,2)) -> 1.02 | F8: =ROUND(AVERAGE(E6:E8),2) -> 3.64
B9: 45962 | C9: =SUM('Trade Book'!Q152:Q170) -> 18018 | D9: 1200000 | E9: =IF(C9 ="N/A","", ROUND(C9*100/D9,2)) -> 1.5 | F9: =ROUND(AVERAGE(E7:E9),2) -> 2.64
B10: 45992 | C10: =SUM('Trade Book'!Q171:Q192) -> 63457 | D10: 1200000 | E10: =IF(C10 ="N/A","", ROUND(C10*100/D10,2)) -> 5.29 | F10: =ROUND(AVERAGE(E8:E10),2) -> 2.6
B11: 46023 | C11: =SUM('Trade Book'!Q193:Q212) -> 610 | D11: 1200000 | E11: =IF(C11 ="N/A","", ROUND(C11*100/D11,2)) -> 0.05 | F11: =ROUND(AVERAGE(E9:E11),2) -> 2.28
B12: 46054 | C12: =SUM('Trade Book'!Q213:Q233) -> 66589 | D12: 1200000 | E12: =IF(C12 ="N/A","", ROUND(C12*100/D12,2)) -> 5.55 | F12: =ROUND(AVERAGE(E10:E12),2) -> 3.63
B13: 46082 | C13: =SUM('Trade Book'!Q234:Q252) -> -48592 | D13: 1200000 | E13: =IF(C13 ="N/A","", ROUND(C13*100/D13,2)) -> -4.05 | F13: =ROUND(AVERAGE(E11:E13),2) -> 0.52
B14: 46113 | C14: =SUM('Trade Book'!Q253:Q271) -> 8918 | D14: 1200000 | E14: =IF(C14 ="N/A","", ROUND(C14*100/D14,2)) -> 0.74 | F14: =ROUND(AVERAGE(E12:E14),2) -> 0.75
B15: 46143 | C15: =SUM('Trade Book'!Q272:Q289) -> 27144 | D15: 1200000 | E15: =IF(C15 ="N/A","", ROUND(C15*100/D15,2)) -> 2.26 | F15: =ROUND(AVERAGE(E13:E15),2) -> -0.35
A16: Total | C16: =SUM(C2:C14) -> 289104 | E16: =SUM(E2:E14) -> 24.08
D17: Average | E17: =ROUND(AVERAGE(E2:E13),1) -> 1.9
B20: Current Capital | C20: 1200000
B21: Percentage Trading gain in current capital | C21: =ROUND(C16*100/C20,1) -> 24.1

Sheet Daily Profit
